Workbook

Sheet processedData
A1: SKU simple | C1: nombre | D1: =LEN(C1) -> 6 | E1: Precio Normal | F1: categorias | G1: categorias | J1: modo_de_uso | K1: tipo_de_piel | L1: principales_ingredientes | M1: descripcion | N1: marca | O1: peso_del_paquete | P1: genero | Q1: modelo | R1: contenido_del_paquete | S1: nombre_general_del_producto | T1: contenido_neto | U1: nombre_de_color | V1: anchura_del_producto | W1: altura_del_producto | X1: largo_del_producto | Y1: etiquetas | Z1: volumen | AA1: caracteristicas | AB1: terminos_de_busqueda | AC1: color | AD1: peso_del_producto | AE1: titulo_seo | AF1: composicion | AG1: fabricante | AH1: descripcion_seo | AI1: aroma | AJ1: categoria_meli | AL1: categoria_ripley | AN1: categoria_falabella | AP1: descripcion_corta
A2: 093-001-003 | B2: =VLOOKUP(A2,Hoja1!B:C,2,0) -> 1 | C2: Pack Dúo Cremas Nocturnas Martiderm Amatist Night Cream 50Ml | D2: =LEN(C2) -> 60 | E2: 232.88 | F2: Antiedad, Facial, Piel Madura | G2: Antiedad | H2: =VLOOKUP(G2,Hoja1!B:C,2,0) -> #N/A | J2: 1. Toma una pequeña cantidad de crema usando la espátula incluida. 2. Aplica diariamente sobre el rostro, cuello y escote. 3. Realiza un suave masaje con movimientos circulares hasta que el producto se absorba completamente. | K2: Piel Madura | L2: Phyto-Retinol (renovación celular suave), Rosa Mosqueta (regeneración e hidratación), Proteoglicanos (firmeza y elasticidad), Omega 3, 6 y 9 (nutrición y barrera protectora), Amatista (propiedades calmantes y energéticas). | M2: ¡Descubre la luminosidad de tu piel madura con este pack duplicado! El Pack de 2 Cremas Nocturnas Martiderm Amatist Night Cream 50Ml es un tratamiento intensivo diseñado para nutrir y revitalizar la piel durante la noche. Esta crema de textura rica está formulada específicamente para pieles maduras que buscan lucir vitales y radiantes, sin necesidad de tratamientos agresivos. Su innovadora fórmula combina activos de alta eficacia como proteoglicanos para mejorar la firmeza, phyto-retinol para una renovación celular suave, aceite de rosa mosqueta para regenerar e hidratar, y una combinación de Omega 3, 6 y 9 para nutrir en profundidad y fortalecer la barrera cutánea. Aprovecha las horas de descanso para una acción reparadora máxima. ¡Invierte en tu belleza nocturna y despierta con una piel visiblemente más lisa, nutrida y llena de vida! | N2: Martiderm | O2: 0.25 | P2: Femenino | Q2: Amatist Night Cream | R2: 2 frascos de crema Martiderm Amatist Night Cream de 50 ml cada uno. | S2: Crema de Noche Antiedad | T2: 100 ml | V2: 5 | W2: 5 | X2: 12 | Y2: crema noche, antiedad, piel madura, martiderm, amatist, revitalizante, phyto-retinol, rosa mosqueta | Z2: 100 | AA2: Tratamiento nocturno, Textura rica y nutritiva, Con espátula incluida, Fórmula para piel madura, Acción revitalizante | AB2: crema nocturna, crema para piel madura, martiderm amatist, tratamiento antiedad, crema de noche, phyto retinol, crema revitalizante, pack cremas, oferta crema facial | AD2: 0.2 | AE2: Pack 2 Cremas Nocturnas Martiderm Amatist - Piel Madura | AF2: Formulada con una combinación de activos innovadores: Proteoglicanos para mejorar la densidad y elasticidad de la piel; Phyto-Retinol, una alternativa vegetal al retinol que renueva las células de forma suave; Aceite de Rosa Mosqueta, rico en ácidos grasos y vitaminas para regenerar e hidratar; y Omega 3, 6 y 9 que nutren y reparan la barrera lipídica cutánea. | AH2: Pack con 2 cremas nocturnas Martiderm Amatist. Tratamiento intensivo para piel madura con Proteoglicanos y Phyto-Retinol. Nutre, revitaliza y mejora la firmeza mientras duermes. ¡Compra ahora! | AJ2: Cuidado Facial | AK2: MPE392452 | AL2: TRATAMIENTOS Y DERMOCOSMETICA > DERMOCOSMETICA | AM2: R300806000000 | AN2: Cuidado de la piel|hidratación de la piel | AO2: 2257 | AP2: 2 unidades de Martiderm Amatist Night Cream de 50Ml cada una.
A3: 069-001-007 | B3: =VLOOKUP(A3,Hoja1!B:C,2,0) -> 2 | C3: Pack Dúo Avene Vitamina Cg Serum 30ML (x2) | D3: =LEN(C3) -> 42 | E3: 243.2 | F3: Antiedad, Antimanchas, Facial | G3: Antiedad | H3: =VLOOKUP(G3,Hoja1!B:C,2,0) -> #N/A | J3: 1. Limpia y seca tu rostro antes de aplicar el sérum. 2. Usa la pipeta para depositar unas gotas en la palma de tu mano. 3. Aplica en rostro, cuello y escote, masajeando suavemente hasta su absorción. 4. Úsalo por la mañana y noche antes de tu crema hidratante. 5. No olvides complementar con protector solar durante el día. | K3: Piel sensible | L3: Vitamina Cg (1.8%): Potente antioxidante que ilumina y protege la piel, Niacinamida (3%): Mejora la barrera cutánea, regenera la piel y reduce manchas, Bakuchiol (1.5%): Alternativa natural al retinol, corrige arrugas sin irritar, 94% de Ingredientes Naturales: Fórmula respetuosa con la piel y el medio ambiente. | M3: ¡Descubre el poder de la luminosidad y la corrección con el Pack Avene Vitamina Cg Serum 30ML (x2)! Este pack incluye dos unidades del revolucionario sérum corrector e iluminador de Avene, diseñado específicamente para combatir los signos visibles del envejecimiento como manchas, arrugas y flacidez. Su fórmula está enriquecida con un poderoso complejo antioxidante de Vitamina Cg estabilizada, Niacinamida y Bakuchiol, un activo natural que actúa como alternativa al retinol. Con un 94% de ingredientes de origen natural y una textura ligera de rápida absorción, es ideal incluso para las pieles más sensibles. Aplica por la mañana y noche para notar en 15 días una piel más suave, rellena, uniforme y radiante. ¡Tu rutina antiedad más completa y efectiva al mejor precio! | N3: Avene | O3: 0.25 | P3: Unisex | Q3: Vitamina Cg Serum | R3: 2 frascos de sérum Avene Vitamina Cg de 30 ml cada uno, cada uno con pipeta dosificadora. | S3: Sérum facial con vitamina C | T3: 60 ml | V3: 4 | W3: 12 | X3: 4 | Y3: sérum vitamina C, antiedad, iluminador, corrector manchas, piel sensible, bakuchiol, niacinamida, antioxidante, cuidado facial, Avene | Z3: 60 | AA3: Corrector e iluminador, Fórmula con 94% ingredientes naturales, Textura ligera de rápida absorción, Ideal para piel sensible, Combate manchas, arrugas y flacidez | AB3: avene vitamina cg serum, sérum vitamina c, sérum antiedad, sérum iluminador, corrector de manchas, bakuchiol, niacinamida, piel sensible, pack sérum, oferta sérum facial | AD3: 0.2 | AE3: Pack Avene Vitamina Cg Serum x2 - Sérum Antiedad Piel Sensible | AF3: Agua, Glicerina, Vitamina Cg (Ascorbil Glucósido 1.8%), Niacinamida (3%), Bakuchiol (1.5%), y otros ingredientes de origen natural. La Vitamina Cg ilumina y protege, la Niacinamida refuerza la barrera y el Bakuchiol actúa como retinol natural para corregir arrugas. | AH3: Pack con 2 sérum Avene Vitamina Cg 30ml. Fórmula correctora e iluminadora con 94% ingredientes naturales, ideal para piel sensible. Combate arrugas, manchas y flacidez. ¡Resultados en 15 días! | AJ3: Cuidado Facial | AK3: MPE392452 | AL3: TRATAMIENTOS Y DERMOCOSMETICA > DERMOCOSMETICA | AM3: R300806000000 | AN3: Cuidado de la piel|hidratación de la piel | AO3: 2257 | AP3: Este pack contiene 2 unidades de Avene Vitamina Cg Serum de 30ML cada una.
A4: 143-001-012 | B4: =VLOOKUP(A4,Hoja1!B:C,2,0) -> 3 | C4: Pack Dúo Bioderma Sensibio Gel Moussant 500ml (x2) - micelar limpiador y calmante piel sensible | D4: =LEN(C4) -> 95 | E4: 159.9 | F4: Facial, Limpiadores, Piel sensible | G4: Facial | H4: =VLOOKUP(G4,Hoja1!B:C,2,0) -> #N/A | J4: 1. Aplicar el gel sobre la piel húmeda del rostro. 2. Masajear suavemente para formar espuma. 3. Aclarar abundantemente con agua. 4. Secar la piel con una toalla con suaves toques. Se puede usar por la mañana y por la noche. | K4: Piel Sensible | L4: Complejo DAF: refuerza el umbral de tolerancia de la piel sensible, Glucósido de coco/Oleato de glicerilo: ingrediente que imita la estructura de la piel, hidrata y restaura lípidos, Agua (AQUA): base del producto, Sodium Cocoamphoacetate: agente limpiador suave, Propanediol: humectante y solvente suave. | M4: ¡Descubre la limpieza suave y eficaz para tu piel sensible! Este pack incluye dos botellas de 500ml del Bioderma Sensibio Gel Moussant, el gel micelar limpiador y calmante formulado específicamente para reforzar la hidratación natural. Su textura en gel se transforma en una espuma delicada que limpia en profundidad, elimina el maquillaje (incluso el de ojos) y calma las irritaciones gracias al exclusivo complejo DAF. Enriquecido con glucósido de coco/oleato de glicerilo, un activo que mimetiza la estructura cutánea, este producto restaura la barrera lipídica, hidrata y mantiene el pH fisiológico. Es no comedogénico, sin jabón y sin perfume, ofreciendo una tolerancia excelente. Ideal para tu rutina diaria de mañana y noche. ¡Consigue un rostro limpio, fresco y perfectamente calmado con este práctico pack doble! | N4: Bioderma | O4: 1.2 | P4: Unisex | Q4: Sensibio Gel Moussant | R4: 2 unidades de Bioderma Sensibio Gel Moussant de 500ml cada una. | S4: Gel limpiador micelar facial | T4: 2 x 500 ml | U4: Transparente | V4: 8 | W4: 20 | X4: 8 | Y4: bioderma, sensibio, gel moussant, limpiador, micelar, calmante, piel sensible, sin perfume, hidratante, espuma | Z4: 1000 | AA4: Gel micelar, Limpia y desmaquilla, Formula calmante, Refuerza la hidratación, Sin jabón, Sin perfume, pH fisiológico, No comedogénico, Para piel sensible | AB4: bioderma sensibio gel, gel limpiador bioderma, limpiador para piel sensible, gel moussant, pack bioderma, oferta bioderma, gel micelar, limpieza facial, piel sensible, desmaquillante | AC4: Transparente | AD4: 1 | AE4: Pack Doble Bioderma Sensibio Gel Moussant 500ml - Piel Sensible | AF4: Agua (AQUA), Sodium Cocoamphoacetate (tensioactivo limpiador suave), Propanediol (humectante), Sodium Lauroyl Sarcosinate (tensioactivo), Citric Acid (regulador de pH), Coco-Glucoside (tensioactivo suave de origen natural), Glyceryl Oleate (emoliente y restaurador lipídico), Sodium Citrate (regulador de pH), y otros ingredientes como Mannitol, Xylitol, Rhamnose, Fructooligosaccharides (componentes del complejo DAF que refuerzan la tolerancia cutánea), y Tocopherol (antioxidante). | AG4: Bioderma | AH4: Pack con 2 unidades de Bioderma Sensibio Gel Moussant 500ml. Gel micelar limpiador y calmante para piel sensible, elimina maquillaje, hidrata y refuerza la barrera de la piel sin irritar. Sin perfume y no comedogénico. | AI4: Sin perfume | AJ4: Cuidado Facial | AK4: MPE392452 | AL4: TRATAMIENTOS Y DERMOCOSMETICA > DERMOCOSMETICA | AM4: R300806000000 | AN4: Limpiadores|desmaquilladores no eléctricos | AO4: 1754 | AP4: Este pack contiene 2 unidades del producto Bioderma Sensibio Gel Moussant de 500ml cada una.
A5: 112-001-002 | B5: =VLOOKUP(A5,Hoja1!B:C,2,0) -> 4 | C5: Pack Tratamiento Antiedad Sesderma Retisil Crema Intensiva + Contorno de Ojos y Labios | D5: =LEN(C5) -> 86 | E5: 458.9 | F5: Antiedad, Facial, Antiarrugas | G5: Antiedad | H5: =VLOOKUP(G5,Hoja1!B:C,2,0) -> #N/A | J5: 1. Para la Crema Intensiva: Aplicar mañana y noche sobre el rostro, cuello y escote con la piel limpia y seca. Masajear suavemente hasta su completa absorción. Usar protector solar diariamente. 2. Para el Contorno de Ojos y Labios: Aplicar mañana y noche en el contorno de ojos y labios con la piel limpia y seca. Aplicar desde el interior hacia el exterior con ligeros toques con los dedos y masajear suavemente. | K5: Todo tipo de piel | L5: Hidroxipinacolona retinoato (reduce arrugas), Péptidos Syn®-Tacks / Syn®-Coll (reafirma la piel), Ácido hialurónico (hidrata y rellena), Silicio orgánico (mejora firmeza), Vitamina E y Centella asiática (antioxidantes), Aceite de rosa mosqueta y almendras dulces (hidratan y suavizan), Cafeína (mejora ojeras), Fitomenadiona epóxido (aclara ojeras). | M5: ¡Transforma tu rutina de belleza con el Pack Pro-Aging Sesderma Retisil! Este exclusivo set combina la poderosa Crema Intensiva para rostro, cuello y escote con el especializado Contorno de Ojos y Labios, diseñados para una acción antiedad integral. La Crema Intensiva, con su avanzado sistema Ageless Beauty, reduce arrugas, reafirma la piel y mejora la flacidez, manchas y textura irregular gracias a ingredientes como el hidroxipinacolona retinoato, péptidos y ácido hialurónico. El Contorno de Ojos y Labios actúa específicamente en las zonas más delicadas, hidratando, aclarando ojeras y reduciendo arrugas locales con activos como cafeína y fitomenadiona. Fabricados con tecnología dermocosmética de alta calidad, ofrecen una hidratación profunda y resultados visibles. ¡Consigue una piel más firme, lisa y radiante con este dúo de tratamiento especializado! | N5: Sesderma | O5: 0.35 | P5: Femenino | Q5: Retisil | R5: 1 frasco de Crema Intensiva Sesderma Retisil, 1 frasco de Contorno de Ojos y Labios Sesderma Retisil. | S5: Pack de Cremas Antiedad Facial | T5: 2 pzas | U5: Blanco | V5: 12 | W5: 8 | X5: 18 | Y5: antiedad, antiarrugas, crema facial, contorno de ojos, pro-aging, sesderma, retisil, hidratante, reafirmante, ojeras | AA5: Reduce arrugas, Reafirma la piel, Mejora la flacidez, Aclara ojeras, Hidratación intensiva, Antioxidante, Para rostro, cuello y escote, Para contorno de ojos y labios | AB5: pack sesderma retisil, crema antiedad, contorno de ojos, tratamiento facial, crema para arrugas, crema pro aging, sesderma retisil crema, crema para ojeras, rutina antiedad | AC5: Blanco | AD5: 0.3 | AE5: Pack Sesderma Retisil - Crema Antiedad y Contorno de Ojos | AF5: Crema Intensiva: Contiene hidroxipinacolona retinoato (análogo de retinol), péptidos (Syn®-Tacks, Syn®-Coll), ácido hialurónico, silicio orgánico, vitamina E, centella asiática, aceite de rosa mosqueta y aceite de almendras dulces para combatir los signos de la edad. Contorno de Ojos: Formulado con cafeína (descongestivo), fitomenadiona epóxido (aclarante), hidroxipinacolona retinoato, péptidos (palmitoil tripéptido-5), ácido hialurónico y extracto de centella asiática para tratar la delicada piel del contorno ocular y labial. | AG5: Sesderma | AH5: Pack antiedad Sesderma Retisil con Crema Intensiva y Contorno de Ojos. Reduce arrugas, reafirma, hidrata y aclara ojeras. Tratamiento facial completo para una piel más joven. | AJ5: Cuidado Facial | AK5: MPE392452 | AL5: TRATAMIENTOS Y DERMOCOSMETICA > DERMOCOSMETICA | AM5: R300806000000 | AN5: Cuidado de la piel|hidratación de la piel | AO5: 2257 | AP5: Este pack contiene: 1 unidad de Sesderma Retisil Crema Intensiva y 1 unidad de Sesderma Retisil Contorno de Ojos y Labios.
A6: 142-001-012 | B6: =VLOOKUP(A6,Hoja1!B:C,2,0) -> 5 | C6: Pack Bioderma Pigmentbio H2O - Agua Micelar Iluminadora x2 Unidades - Tratamiento Manchas | D6: =LEN(C6) -> 89 | E6: 88.9 | F6: Antimanchas, Facial, Limpiadores | G6: Antimanchas | H6: =VLOOKUP(G6,Hoja1!B:C,2,0) -> #N/A | J6: 1. Humedece un algodón con el agua micelar. 2. Limpia y elimina el maquillaje del rostro y los ojos con suavidad. 3. Seca la piel con suavidad. Uso diario, no necesita enjuague. | K6: Piel hiperpigmentada | L6: Hexapeptide-2 (BI 520): Regula la pigmentación y aclara manchas, Ácido Azelaico: Actúa sobre los mecanismos de las manchas oscuras, Extracto de Andrographis Paniculata: Propiedades iluminadoras, Fructooligosacáridos: Protege y respeta el equilibrio de la piel. | M6: ¡Consigue un tono de piel radiante y uniforme! Este pack contiene dos botellas de Agua Micelar Iluminadora Bioderma Pigmentbio H2O de 250 ml. Especialmente formulada para pieles con trastornos de pigmentación como manchas oscuras, esta solución micelar de alta tolerancia limpia, desmaquilla e ilumina en un solo gesto. Su tecnología con micelas elimina impurezas y maquillaje respetando el equilibrio cutáneo, mientras que su combinación patentada de activos como el Hexapeptide-2 (BI 520) y el Ácido Azelaico regula los mecanismos biológicos que causan las manchas. Sin perfume, es ideal para uso diario en rostro y ojos, dejando una sensación de frescura y luminosidad inmediata. ¡El dúo perfecto para una rutina antimanchas efectiva y suave! | N6: Bioderma | O6: 0.7 | P6: Unisex | Q6: Pigmentbio H2O | R6: 2 botellas de agua micelar Bioderma Pigmentbio H2O de 250 ml. | S6: Agua micelar iluminadora | T6: 500 ml | U6: Transparente | V6: 6.5 | W6: 18 | X6: 6.5 | Y6: agua micelar, bioderma, pigmentbio, iluminadora, antimanchas, desmaquillante, limpiador, piel hiperpigmentada, sin perfume, alta tolerancia | Z6: 500 | AA6: Alta tolerancia, Sin perfume, Desmaquilla rostro y ojos, No necesita enjuague, Efecto iluminador, Regula la pigmentación | AB6: agua micelar bioderma, pigmentbio h2o, agua iluminadora, desmaquillante para manchas, limpiador facial antimanchas, bioderma pigmentbio, pack agua micelar, oferta bioderma, tratamiento hiperpigmentación, rutina para manchas | AC6: Transparente | AD6: 0.6 | AE6: Pack Bioderma Pigmentbio H2O Agua Micelar Iluminadora x2 | AF6: Agua (Aqua), tensioactivos suaves (PEG-6 Caprylic/Capric Glycerides, Polysorbate 20), agentes hidratantes y de protección (Dipropylene Glycol, Butylene Glycol, Fructooligosaccharides, Mannitol, Xylitol), activos antimanchas (Azelaic Acid, Hexapeptide-2 [BI 520]), extracto botánico iluminador (Andrographis Paniculata Leaf Extract), y agentes quelantes y conservantes. Fórmula sin perfume. | AG6: Bioderma | AH6: Pack con 2 aguas micelares Bioderma Pigmentbio H2O. Limpia, desmaquilla e ilumina pieles con manchas. Alta tolerancia y sin perfume. ¡Consigue un tono uniforme! | AI6: Sin perfume | AJ6: Desmaquillantes | AK6: MPE392393 | AL6: TRATAMIENTOS Y DERMOCOSMETICA > DERMOCOSMETICA | AM6: R300806000000 | AN6: Limpiadores|desmaquilladores no eléctricos | AO6: 1754 | AP6: 2 unidades de Agua Micelar Bioderma Pigmentbio H2O de 250 ml cada una.
A7: 092-001-003 | B7: =VLOOKUP(A7,Hoja1!B:C,2,0) -> 6 | C7: Pack Dúo Martiderm Epigence 145 Cream - Crema Antiarrugas y Luminosidad (2 x 50ml) | D7: =LEN(C7) -> 82 | E7: 396.42 | F7: Antiedad, Antiarrugas, Facial | G7: Antiedad | H7: =VLOOKUP(G7,Hoja1!B:C,2,0) -> #N/A | J7: 1. Toma una pequeña cantidad de crema usando la espátula incluida. 2. Aplica diariamente por la mañana sobre el rostro, cuello y escote. 3. Realiza un suave masaje con movimientos circulares hasta que el producto se absorba por completo. | K7: Todo tipo de piel | L7: Epigen 145: Reprograma la piel para retrasar el envejecimiento. Hyaluronic Gold: Aumenta la producción de ácido hialurónico para hidratación y volumen. Proteum 89+: Mejora la firmeza y elasticidad de la piel. | M7: ¡Descubre la fórmula rejuvenecedora y consigue una piel visiblemente más joven! El Pack Doble de Martiderm Epigence 145 Cream es tu aliado perfecto contra los signos de la edad. Esta crema facial de tratamiento diario está específicamente diseñada para reprogramar la piel y retrasar el envejecimiento cutáneo. Su avanzada tecnología actúa a tres niveles: reactiva la capacidad natural de regeneración celular, estimula la producción de colágeno, elastina y ácido hialurónico, y aumenta la firmeza y elasticidad. Con ingredientes como Epigen 145, Hyaluronic Gold y Proteum 89+, no solo reduce arrugas y líneas de expresión, sino que también aporta una luminosidad extraordinaria y unifica el tono de la piel. Ideal para todo tipo de piel, su textura se absorbe rápidamente sin dejar residuos grasos. ¡Invierte en tu piel y disfruta de un aspecto renovado, firme y radiante con este pack de dos unidades! | N7: Martiderm | O7: 0.25 | P7: Unisex | Q7: Epigence 145 Cream | R7: 2 frascos de crema Martiderm Epigence 145 Cream de 50ml cada uno (cada uno incluye espátula). | S7: Crema antiarrugas y antiedad facial | T7: 100 ml (2 x 50 ml) | V7: 5 | W7: 10 | X7: 5 | Y7: antiedad, antiarrugas, crema facial, luminosidad, firmeza, ácido hialurónico, colágeno, elastina, Martiderm, Epigence | Z7: 100 | AA7: Reduce arrugas, Aporta luminosidad, Aumenta firmeza y elasticidad, Estimula producción de colágeno, Unifica el tono de la piel, Para uso diario | AB7: crema antiarrugas, Martiderm Epigence, crema antiedad, tratamiento facial, crema con ácido hialurónico, crema para piel madura, crema luminosidad, pack crema facial | AD7: 0.2 | AE7: Pack Doble Crema Antiarrugas Martiderm Epigence 145 - 2x50ml | AF7: Ingredientes inteligentes que incluyen Epigen 145 (activo que reprograma la piel), Hyaluronic Gold (complejo de ácido hialurónico para hidratación profunda) y Proteum 89+ (potenciador de firmeza y elasticidad). Formulada con vitaminas para iluminar y unificar el tono cutáneo. | AH7: Pack con 2 cremas Martiderm Epigence 145 de 50ml. Reduce arrugas, aporta luminosidad y firmeza. Actúa estimulando colágeno y ácido hialurónico. Para todo tipo de piel. ¡Renueva tu piel! | AJ7: Cuidado Facial | AK7: MPE392452 | AL7: TRATAMIENTOS Y DERMOCOSMETICA > DERMOCOSMETICA | AM7: R300806000000 | AN7: Cuidado de la piel|hidratación de la piel | AO7: 2257 | AP7: Este pack contiene 2 unidades de Martiderm Epigence 145 Cream de 50ml cada una.
A8: 071-001-007 | B8: =VLOOKUP(A8,Hoja1!B:C,2,0) -> 7 | C8: Pack Avene Sérums Hyaluron Activ B3 + Vitamina Cg - Tratamiento Antiedad Completo Piel Sensible | D8: =LEN(C8) -> 95 | E8: 460.1 | F8: Antiedad, Facial, Antimanchas | G8: Antiedad | H8: =VLOOKUP(G8,Hoja1!B:C,2,0) -> #N/A | J8: 1. Limpia y seca tu rostro, cuello y escote. 2. Para el Sérum Hyaluron Activ B3: Aplica 1-2 gotas 1 o 2 veces al día, solo o antes de tu crema habitual. 3. Para el Sérum Vitamina Cg: Usa la pipeta para aplicar unas gotas por la mañana y noche, masajeando suavemente hasta su absorción. 4. Complementa con protector solar durante el día, especialmente cuando uses el sérum de Vitamina C. | K8: Piel sensible | L8: Ácido Hialurónico (1.5%): Hidrata y rellena arrugas al retener agua en la piel. Niacinamida (6% en Hyaluron, 3% en Vitamina Cg): Mejora la barrera cutánea, reduce manchas y regenera. Vitamina Cg (1.8%): Potente antioxidante que ilumina y protege contra el daño ambiental. Bakuchiol (1.5%): Alternativa natural al retinol, corrige arrugas sin irritar. Agua Termal de Avène: Calma, suaviza y reduce la sensibilidad de la piel. | M8: ¡Descubre la sinergia perfecta para una piel radiante y rejuvenecida! Este pack exclusivo combina dos sérums de alta eficacia de los Laboratorios Avène: el Sérum Hyaluron Activ B3 y el Sérum Vitamina Cg. El Hyaluron Activ B3 es un concentrado de ácido hialurónico puro (1.5%) y niacinamida (6%) que actúa sobre la causa del envejecimiento, alargando la vida de las células. Su fórmula minimalista de solo 8 ingredientes ofrece un efecto tensor, logrando en 15 días una piel más firme, elástica y con arrugas reducidas. Por su parte, el Sérum Vitamina Cg, con un 94% de ingredientes naturales, es un corrector e iluminador que combate manchas, arrugas y flacidez gracias a su potente combinación de Vitamina Cg (1.8%), Niacinamida (3%) y Bakuchiol (1.5%). Ambos productos, sin perfume y probados en pieles sensibles, ofrecen una textura ligera de rápida absorción. ¡La dupla ideal para un cuidado facial avanzado, seguro y visiblemente efectivo! | N8: Avène | O8: 0.25 | P8: Unisex | Q8: Hyaluron Activ B3 + Vitamina Cg Pack | R8: 1 frasco de Sérum Avène Hyaluron Activ B3 de 30 ml, 1 frasco de Sérum Avène Vitamina Cg de 30 ml. | S8: Pack de Sérums Faciales Antiedad | T8: 2 pzas (60 ml en total) | U8: Transparente | V8: 6 | W8: 15 | X8: 12 | Y8: avène, sérum, ácido hialurónico, vitamina c, antiedad, antimanchas, niacinamida, bakuchiol, piel sensible, facial, tratamiento, pack, oferta | Z8: 60 | AA8: Sin perfume, Probado en pieles sensibles, Fórmula minimalista, Textura ligera de rápida absorción, Con Agua Termal de Avène, Envase con pipeta | AB8: pack avène sérum, avène hyaluron activ b3, avène vitamina cg, sérum antiedad, sérum para manchas, tratamiento facial piel sensible, ácido hialurónico y vitamina c, niacinamida sérum, bakuchiol, oferta sérums avène | AC8: Transparente | AD8: 0.2 | AE8: Pack Sérums Avène: Hyaluron B3 + Vitamina Cg - Antiedad | AF8: Agua Termal de Avène (calmante), Ácido Hialurónico de alto y bajo peso molecular (hidratante y rellenador), Niacinamida (reparadora y uniformizante), Vitamina Cg (antioxidante e iluminadora), Bakuchiol (renovador celular suave), Glicerina (humectante). Fórmulas diseñadas para máxima tolerancia. | AG8: Laboratorios Dermatológicos Avène | AH8: Pack con 2 sérums Avène: Hyaluron Activ B3 (ácido hialurónico) y Vitamina Cg. Combate arrugas, manchas y flacidez. Ideal para piel sensible. Textura ligera y sin perfume. ¡Resultados en 15 días! | AI8: null | AJ8: Cuidado Facial | AK8: MPE392452 | AL8: TRATAMIENTOS Y DERMOCOSMETICA > DERMOCOSMETICA | AM8: R300806000000 | AN8: Cuidado de la piel|hidratación de la piel | AO8: 2257 | AP8: Este pack contiene: 1 Sérum Avène Hyaluron Activ B3 y 1 Sérum Avène Vitamina Cg de 30ML.
A9: 090-001-006 | B9: =VLOOKUP(A9,Hoja1!B:C,2,0) -> 8 | C9: Pack Tratamiento Contorno de Ojos - Frezyderm Eye Balm 15 ml y Color Eye Balm 15 ml | D9: =LEN(C9) -> 83 | E9: 296 | F9: Antiarrugas, Antiojeras, Antiedad | G9: Antiarrugas | H9: =VLOOKUP(G9,Hoja1!B:C,2,0) -> #N/A | J9: 1. Limpia tu rostro y la zona del contorno de ojos. 2. Aplica una pequeña cantidad del bálsamo (Eye Balm o Color Eye Balm) con suaves toques alrededor del ojo, desde el interior hacia el exterior. 3. Usa diariamente por la mañana y/o por la noche para mejores resultados. | K9: Todo tipo de piel | L9: Aceite de argán: Hidratante y nutritivo, Proteínas de avena ATP: Reafirmante y lifting, Extracto de crambe maritima: Protege las células madre de la piel, Resveratrol: Mejora la densidad de la piel, Isoflavonas: Acción antiarrugas, Bioflavonoides: Activan la microcirculación para reducir ojeras | M9: ¡Descubre el dúo perfecto para una mirada rejuvenecida y radiante! Este pack exclusivo de Frezyderm incluye dos potentes bálsamos para el contorno de ojos: el Color Eye Balm y el Eye Balm, ambos de 15 ml. Estos productos de alta cosmética están formulados con ingredientes activos como aceite de argán, proteínas de avena ATP, resveratrol y bioflavonoides. Su textura suave y refrescante actúa inmediatamente activando la microcirculación, reduciendo visiblemente las ojeras, la hinchazón (hasta en un 2.7%) y las líneas de expresión. Recupera la elasticidad, luminosidad y firmeza de la piel más delicada de tu rostro. ¡Consigue una apariencia fresca, descansada y juvenil con este tratamiento especializado! | N9: Frezyderm | O9: 0.08 | P9: Unisex | Q9: Color Eye Balm y Eye Balm | R9: 1 frasco de Frezyderm Color Eye Balm de 15 ml, 1 frasco de Frezyderm Eye Balm de 15 ml | S9: Pack de cremas para contorno de ojos | T9: 30 ml (2 x 15 ml) | V9: 3 | W9: 3 | X9: 10 | Y9: contorno de ojos, antiarrugas, antiojeras, frezyderm, bálsamo ocular, crema ojos, hinchazón, mirada fresca, tratamiento ocular, cosmética griega | Z9: 30 | AA9: Reduce hinchazón y ojeras, Activa microcirculación, Recupera elasticidad, Disminuye líneas de expresión, Textura suave y refrescante, Aplicación diaria | AB9: crema contorno de ojos, frezyderm eye balm, pack contorno de ojos, reducir ojeras, antiarrugas ojos, bálsamo para ojos, tratamiento ocular, cosmética griega frezyderm, crema para hinchazón de ojos, mirada cansada | AD9: 0.05 | AE9: Pack Frezyderm Eye Balm y Color Eye Balm - Tratamiento Contorno Ojos | AF9: Formulados con una combinación de aceites naturales (como el de argán), extractos vegetales (crambe maritima), péptidos (Acetyl Tetrapeptide) y antioxidantes (Resveratrol, Isoflavonas, Bioflavonoides). Estos ingredientes trabajan en sinergia para hidratar profundamente, proteger las células de la piel, estimular la renovación celular y mejorar la firmeza y densidad de la piel del contorno ocular. | AH9: Pack con 2 cremas Frezyderm para contorno de ojos. Reduce ojeras, hinchazón y arrugas. Con aceite de argán, resveratrol y bioflavonoides. ¡Consigue una mirada fresca y juvenil! | AJ9: Cuidado Facial | AK9: MPE392452 | AL9: TRATAMIENTOS Y DERMOCOSMETICA > DERMOCOSMETICA | AM9: R300806000000 | AN9: Cuidado de la piel|hidratación de la piel | AO9: 2257 | AP9: Este pack contiene: 1 unidad de Frezyderm Color Eye Balm de 15 ml y 1 unidad de Frezyderm Eye Balm de 15 ml.
A10: 090-001-003 | B10: =VLOOKUP(A10,Hoja1!B:C,2,0) -> 9 | C10: Pack Dúo Martiderm Proteos Screen SPF 50+ - 2 unidades de 40ml cada una | D10: =LEN(C10) -> 71 | E10: 125.23 | F10: Facial, Antiedad, SolaresHacer principal | G10: Facial | H10: =VLOOKUP(G10,Hoja1!B:C,2,0) -> #N/A | J10: 1. Aplicar una cantidad generosa sobre el rostro, cuello y escote limpios y secos. 2. Realizar un suave masaje con movimientos circulares ascendentes hasta su total absorción. 3. Usar diariamente por la mañana, como último paso de tu rutina de cuidado facial, antes del maquillaje. 4. Reaplicar cada 2 horas si se está expuesto al sol de forma continua o después de nadar o sudar. | K10: Todo tipo de piel | L10: Proteoglicanos: Previenen y reducen los signos del envejecimiento, aportando firmeza y elasticidad a la piel. Complejo de ácido hialurónico y silicio: Ayuda a mantener la piel con aspecto joven, fresco y uniforme, proporcionando hidratación y soporte. | M10: ¡Protege y rejuvenece tu piel todos los días con el Pack Doble de Martiderm Proteos Screen SPF 50+! Este pack incluye dos unidades de la revolucionaria crema facial fluida con Factor de Protección Solar 50+. Su fórmula de fácil absorción y textura Cream-to-Powder no solo previene el envejecimiento cutáneo prematuro causado por el sol, sino que también ayuda a reparar los signos existentes, dejando una sensación sedosa e invisible. Ofrece una protección de amplio espectro contra rayos UVA, UVB, infrarrojos (IR) y luz azul (HEV). Enriquecida con proteoglicanos y un complejo exclusivo de ácido hialurónico y silicio, este tratamiento diario mantiene tu piel con un aspecto joven, fresco, uniforme, firme y elástico. Es el aliado perfecto, práctico y polivalente para tu rutina diaria, ideal para todas las edades y para deportistas, ya que su rápida absorción y tacto seco evitan que pique en los ojos. ¡Consigue una protección superior y un cuidado antiedad en un solo gesto! | N10: Martiderm | O10: 0.15 | P10: Unisex | Q10: Proteos Screen SPF50+ | R10: 2 unidades de crema facial protectora Martiderm Proteos Screen SPF 50+, de 40ml cada una. | S10: Protector facial con FPS y tratamiento antiedad | T10: 2 x 40 ml | V10: 4 | W10: 12 | X10: 4 | Y10: protector solar facial, fps 50, antiedad, amplio espectro, ácido hialurónico, proteoglicanos, textura fluida, protección uva uvb, luz azul, crema facial | Z10: 80 | AA10: FPS 50+, Protección de amplio espectro (UVA/UVB/IR/HEV), Textura Cream-to-Powder, Rápida absorción, Tacto seco, No pica los ojos, Con proteoglicanos y ácido hialurónico | AB10: protector solar facial martiderm, proteos screen, fps 50 crema facial, bloqueador facial antiedad, protector solar con ácido hialurónico, crema con proteccion solar, martiderm spf 50, pack protector solar, doble protector facial, crema facial fps | AC10: Blanco | AD10: 0.08 | AE10: Pack Doble Protector Facial Martiderm Proteos Screen SPF 50+ 40ml | AF10: Fórmula que combina filtros solares de amplio espectro con activos antiedad como proteoglicanos (para firmeza y elasticidad) y un complejo de ácido hialurónico y silicio (para hidratación y uniformidad). Su base de textura fluida (Cream-to-Powder) asegura una aplicación cómoda y un acabado invisible. | AH10: Pack con 2 protectores faciales Martiderm SPF 50+. Protección UVA/UVB/IR/luz azul + tratamiento antiedad con proteoglicanos y ácido hialurónico. Textura fluida de rápida absorción. ¡Tu defensa diaria! | AJ10: Cuidado Facial | AK10: MPE392452 | AL10: PROTECTORES SOLARES | AM10: R300804000000 | AN10: Productos de protección solar | AO10: 492 | AP10: Este pack contiene 2 unidades de Martiderm Proteos Screen SPF 50+ de 40ml cada una.
A11: 087-001-003 | B11: =VLOOKUP(A11,Hoja1!B:C,2,0) -> 10 | C11: Pack Martiderm Gel Micelar Limpiador 200ml + Solución Micelar Limpiadora 300ml | D11: =LEN(C11) -> 78 | E11: 200.8 | F11: Facial, Limpiadores, Hidratante | G11: Facial | H11: =VLOOKUP(G11,Hoja1!B:C,2,0) -> #N/A | J11: 1. Para el Gel Micelar: Aplica sobre el rostro húmedo, masajea suavemente y aclara con abundante agua. 2. Para la Solución Micelar: Impregna un disco desmaquillante, deslízalo por rostro, cuello y escote para retirar impurezas y maquillaje. No requiere aclarado. | K11: Todo tipo de piel | L11: Extracto de Edelweiss: Potente antioxidante que protege e hidrata la piel, Prebióticos: Favorecen el equilibrio de la flora cutánea y la defensa natural. | M11: ¡Transforma tu rutina de limpieza con este pack exclusivo de Martiderm! Este combo incluye el Gel Micelar Limpiador de 200ml y la Solución Micelar Limpiadora 3 en 1 de 300ml. El gel, de uso diario, limpia y elimina suavemente las impurezas y el maquillaje sin resecar, dejando la piel fresca e hidratada, ideal para cara, cuello y escote. La solución micelar ofrece una limpieza facial efectiva y suave en tres pasos: desmaquilla, limpia e hidrata. Ambos productos están enriquecidos con extracto de Edelweiss, un antioxidante natural que protege la piel, y prebióticos que equilibran su flora. La combinación perfecta para una limpieza profunda y un cuidado respetuoso, dejando tu piel radiante y preparada para los siguientes pasos de tu ritual de belleza. ¡Consigue una piel impecable con la doble acción de Martiderm! | N11: Martiderm | O11: 0.65 | P11: Unisex | R11: 1 frasco de Gel Micelar Limpiador Martiderm de 200ml, 1 frasco de Solución Micelar Limpiadora Martiderm de 300ml. | S11: Pack de Limpiadores Faciales Micelares | T11: 200 ml + 300 ml | V11: 8 | W11: 20 | X11: 12 | Y11: limpieza facial, micelar, desmaquillante, gel limpiador, solución micelar, edelweiss, prebióticos, piel sensible, rutina facial | Z11: 500 | AA11: Limpieza 3 en 1, Con extracto de Edelweiss, Con prebióticos, Sin aclarado (solución), Para uso diario, Antioxidante, Hidratante | AB11: pack martiderm, gel micelar, solución micelar, limpiador facial, desmaquillante, cuidado de la piel, rutina limpieza, edelweiss, prebióticos | AD11: 0.5 | AE11: Pack Limpiadores Martiderm: Gel y Solución Micelar con Edelweiss | AF11: Formulados con extracto de Edelweiss (Leontopodium alpinum), conocido por sus propiedades antioxidantes que ayudan a proteger la piel del estrés ambiental, y prebióticos que favorecen el equilibrio de la microbiota cutánea, reforzando su barrera natural. | AH11: Pack Martiderm con Gel y Solución Micelar. Limpia, desmaquilla e hidrata tu piel con extracto de Edelweiss y prebióticos. Ideal para todo tipo de pieles. ¡Completa tu rutina facial! | AJ11: Cuidado Facial | AK11: MPE392452 | AL11: TRATAMIENTOS Y DERMOCOSMETICA > DERMOCOSMETICA | AM11: R300806000000 | AN11: Limpiadores|desmaquilladores no eléctricos | AO11: 1754 | AP11: Este pack contiene: 1 unidad de Gel Micelar Limpiador Martiderm de 200ml y 1 unidad de Solución Micelar Limpiadora Martiderm de 300ml.
A12: 092-001-006 | B12: =VLOOKUP(A12,Hoja1!B:C,2,0) -> 11 | C12: Pack Dúo Frezyderm Velvet Moisturizing 50 ml para Piel Madura (x2) | D12: =LEN(C12) -> 66 | E12: 420 | F12: Antiedad, Hidratante, Facial | G12: Antiedad | H12: =VLOOKUP(G12,Hoja1!B:C,2,0) -> #N/A | J12: 1. Asegúrate de que tu piel del rostro, cuello y escote esté limpia y seca. 2. Toma una cantidad adecuada de crema con los dedos limpios. 3. Aplícala suavemente sobre las áreas mencionadas. 4. Masajea con movimientos circulares ascendentes hasta su completa absorción. 5. Usa como parte de tu rutina de cuidado por la mañana y/o por la noche. | K12: Piel Madura | L12: Cristales de Diamante y Nitruro de Boro: Renuevan las células y aumentan la luminosidad, Colágeno y Elastina Marina: Hidratan y mejoran la elasticidad, Ácido Hialurónico de bajo peso molecular: Hidrata profundamente reteniendo humedad, Ectoína: Protege la piel de contaminantes ambientales, Glucógeno Marino: Protege contra radicales libres y fortalece la piel. | M12: ¡Descubre el secreto para una piel madura radiante y rejuvenecida! Presentamos el Pack Doble de Frezyderm Diamond Velvet Moisturizing Cream, la solución definitiva para combatir la sequedad, la falta de brillo y los signos del envejecimiento. Este pack incluye dos frascos de 50ml de esta crema ultrahidratante de textura aterciopelada, especialmente formulada con tecnología avanzada para pieles maduras y desgastadas. Su fórmula polivalente enriquece la piel con Cristales de Diamante y Nitruro de Boro que aceleran la renovación celular, mientras que una poderosa combinación de colágeno marino, elastina, ácido hialurónico y ectoína garantiza una hidratación activa y pasiva de larga duración. Además, el glucógeno marino fortalece los mecanismos de defensa naturales de la piel, protegiéndola de agresiones externas y radicales libres. Ideal para usar día y noche, esta crema no solo nutre en profundidad sino que también mejora visiblemente la luminosidad y firmeza. ¡Consigue un cutis suave, hidratado y protegido con este increíble pack de valor! | N12: Frezyderm | O12: 0.3 | P12: Unisex | Q12: Diamond Velvet Moisturizing Cream | R12: 2 frascos de crema hidratante Frezyderm Diamond Velvet Moisturizing de 50ml cada uno. | S12: Crema hidratante antiedad | T12: 100 ml | V12: 5 | W12: 5 | X12: 10 | Y12: crema antiedad, hidratante piel madura, frezyderm, diamond velvet, ácido hialurónico, colágeno marino, crema facial, tratamiento facial, renovación celular | Z12: 100 | AA12: Textura aterciopelada, Hidratación prolongada, Renovación celular, Protección ambiental, Fórmula con activos marinos, Para uso diurno y nocturno | AB12: crema frezyderm, velvet moisturizing, crema para piel madura, hidratante con ácido hialurónico, crema antiedad, frezyderm diamond, pack crema facial, tratamiento antienvejecimiento, crema de noche, crema de día | AD12: 0.25 | AE12: Pack 2 Cremas Frezyderm Velvet Moisturizing 50ml - Antiedad | AF12: Agua, ingredientes hidratantes (colágeno marino, elastina marina, ácido hialurónico-silanol, ectoína, complejo similar a NMF), Cristales de Diamante, Nitruro de Boro, Glucógeno Marino. Esta combinación proporciona hidratación profunda, renovación celular y protección ambiental. | AH12: Pack con 2 cremas Frezyderm Velvet Moisturizing 50ml. Hidratación intensa y antiedad para piel madura. Con ácido hialurónico, colágeno marino y protección ambiental. ¡Renueva tu piel! | AJ12: Cuidado Facial | AK12: MPE392452 | AL12: TRATAMIENTOS Y DERMOCOSMETICA > DERMOCOSMETICA | AM12: R300806000000 | AN12: Cuidado de la piel|hidratación de la piel | AO12: 2257 | AP12: Este pack contiene 2 unidades de la crema Frezyderm Diamond Velvet Moisturizing de 50ml cada una.
A13: 054-001-007 | B13: =VLOOKUP(A13,Hoja1!B:C,2,0) -> 12 | C13: Pack Limpieza Facial Avene Espuma Limpiadora 150 ml + Cleanance Gel 200 ml | D13: =LEN(C13) -> 74 | E13: 219.5 | F13: Facial, Limpiadores, Piel grasa | G13: Facial | H13: =VLOOKUP(G13,Hoja1!B:C,2,0) -> #N/A | J13: 1. Para la Espuma Limpiadora: Aplicar en el rostro, sobre la piel mojada o seca. Masajear y luego aclarar con abundante agua. 2. Para el Cleanance Gel: Aplicar una pequeña cantidad sobre la piel húmeda por la mañana y por la noche en rostro, cuello y espalda si es necesario. Formar espuma y enjuagar con abundante agua. | K13: Piel grasa con tendencia acneica | L13: Ácido glutámico (reequilibra la producción de sebo), Agua Termal de Avène 72.5% (calma y reequilibra la piel), Laurato de glicerilo (regula el exceso de sebo y matifica), Extracto de Cardo Mariano (purificante). | M13: ¡Descubre la rutina perfecta para una piel limpia, fresca y sin brillos! Este pack especial de Avène incluye dos limpiadores faciales de alta eficacia. La Espuma Limpiadora de 150 ml es una fórmula cremosa y sin jabón que limpia y desmaquilla suavemente rostro, ojos y labios, eliminando impurezas y exceso de sebo gracias al ácido glutámico, mientras el Agua Termal de Avène calma y reequilibra la piel. El Cleanance Gel de 200 ml es un limpiador purificante que regula el sebo y matifica la piel con su activo vegetal Laurato® de glicerilo, dejando una sensación de frescura extrema. Ideal para una limpieza profunda que respeta el pH natural. ¡Consigue una piel clarificada y luminosa con este dúo infalible! | N13: Avène | O13: 0.45 | P13: Unisex | Q13: Pack Espuma + Cleanance Gel | R13: 1 frasco de Espuma Limpiadora Avène de 150 ml, 1 frasco de Gel Limpiador Cleanance Avène de 200 ml. | S13: Kit de limpieza facial | T13: 350 ml | U13: null | V13: 8 | W13: 20 | X13: 12 | Y13: limpieza facial, piel grasa, acne, espuma limpiadora, gel limpiador, Avène, sebo, matificante, purificante | Z13: 350 | AA13: Limpia y desmaquilla, Regula la producción de sebo, Efecto matificante, Con Agua Termal de Avène, Sin jabón, pH respetuoso | AB13: pack avène limpieza, espuma limpiadora avène, cleanance gel, kit limpieza piel grasa, productos para acne, limpiador facial, avène cleanance, rutina limpieza facial | AC13: Transparente | AD13: 0.35 | AE13: Pack Limpieza Facial Avène - Espuma 150ml + Cleanance Gel 200ml | AF13: Espuma Limpiadora: Agua Termal de Avène (72.5%), ácido glutámico, base limpiadora suave sin jabón. Cleanance Gel: Agua Termal de Avène, Laurato de glicerilo (regulador de sebo), Zinc Gluconate, tensioactivos suaves. Ambos productos están formulados para limpiar profundamente sin agredir la piel. | AG13: Pierre Fabre | AH13: Pack con Espuma Limpiadora y Cleanance Gel de Avène. Ideal para piel grasa y con tendencia acneica. Limpia, purifica, regula el sebo y matifica. ¡Disfruta de una piel fresca y luminosa! | AI13: null | AJ13: Kit de Cuidado de la Piel | AK13: MPE123356 | AL13: TRATAMIENTOS Y DERMOCOSMETICA > DERMOCOSMETICA | AM13: R300806000000 | AN13: Limpiadores|desmaquilladores no eléctricos | AO13: 1754
A14: 093-001-006 | B14: =VLOOKUP(A14,Hoja1!B:C,2,0) -> 13 | C14: Pack Dúo Frezyderm Diamond Wrinkle Fighter 40ml (x2) antienvejecimiento con aplicador | D14: =LEN(C14) -> 85 | E14: 460 | F14: Antiedad, Facial, Tratamiento | G14: Antiedad | H14: =VLOOKUP(G14,Hoja1!B:C,2,0) -> #N/A | J14: 1. Usa como parte de tu rutina nocturna sobre la piel limpia y seca. 2. Gira el cabezal del aplicador para abrirlo. 3. Enrolla las diademas hexagonales de acero inoxidable sobre la piel, distribuyendo y masajeando la fórmula. 4. No apliques crema o suero después. | K14: Todo tipo de piel | L14: Diamond Powder: Renueva las células para una piel radiante y joven, Red Clover: Contrarresta arrugas y aumenta la elasticidad e hidratación, Pisum Sativum: Reduce arrugas y mejora elasticidad, densidad y firmeza, LMW Hyaluronic acid-Silanol: Hidrata y rellena arrugas, Mioinositol: Hidrata y reafirma la piel | M14: ¡Descubre el poder de la innovación antiedad! Pack con 2 unidades del Frezyderm Diamond Wrinkle Fighter 40ml, un tratamiento semanal de lujo para pieles maduras. Este sérum de alta eficacia combate tanto las arrugas estáticas como las dinámicas, gracias a su fórmula enriquecida con Diamond Powder que activa la renovación celular para una piel instantáneamente radiante y rejuvenecida. Su exclusivo aplicador con rodillos hexagonales de acero inoxidable permite una aplicación precisa y un masaje que potencia la absorción de ingredientes clave como el Trébol Rojo, Pisum Sativum, Ácido Hialurónico de bajo peso molecular y Mioinositol. Juntos, estos componentes aumentan la firmeza, densidad, elasticidad e hidratación profunda de la piel. Ideal para incorporar en tu rutina de noche, es el aliado perfecto para una piel más lisa, firme y con un brillo saludable. ¡Transforma tu rutina de cuidado con este tratamiento profesional que ofrece resultados visibles! | N14: Frezyderm | O14: 0.25 | P14: Unisex | Q14: Diamond Wrinkle Fighter | R14: 2 unidades de Frezyderm Diamond Wrinkle Fighter de 40ml cada una. | S14: Tratamiento antienvejecimiento facial | T14: 2 x 40 ml | V14: 5 | W14: 15 | X14: 5 | Y14: antiedad, antienvejecimiento, arrugas, facial, sérum, tratamiento, renovación celular, firmeza, hidratación, Frezyderm, diamond powder, rodillo de acero | Z14: 80 | AA14: Tratamiento semanal, Aplicador con rodillos de acero inoxidable, Fórmula con Diamond Powder, Enfoque en arrugas estáticas y dinámicas, Para uso nocturno | AB14: Frezyderm Wrinkle Fighter, tratamiento arrugas, crema antiedad, sérum facial, diamond powder, rodillo facial, anti aging, piel madura, pack oferta, cuidado de la piel | AD14: 0.2 | AE14: Pack x2 Frezyderm Wrinkle Fighter 40ml - Tratamiento Antiedad | AF14: Fórmula antienvejecimiento que incluye Diamond Powder (polvo de diamante) para renovación celular, extracto de Trébol Rojo (Red Clover) para elasticidad e hidratación, Pisum Sativum para mejorar firmeza y densidad, Ácido Hialurónico de bajo peso molecular (LMW Hyaluronic acid-Silanol) para hidratación y relleno de arrugas, y Mioinositol para reafirmar la piel. | AH14: Pack con 2 tratamientos Frezyderm Wrinkle Fighter 40ml. Combate arrugas estáticas y dinámicas con Diamond Powder y aplicador de rodillos. Ideal para pieles maduras. ¡Resultados visibles! | AJ14: Cuidado Facial | AK14: MPE392452 | AL14: TRATAMIENTOS Y DERMOCOSMETICA > DERMOCOSMETICA | AM14: R300806000000 | AN14: Cuidado de la piel|hidratación de la piel | AO14: 2257 | AP14: Este pack contiene 2 unidades de Frezyderm Diamond Wrinkle Fighter de 40ml cada una.
A15: 057-001-007 | B15: =VLOOKUP(A15,Hoja1!B:C,2,0) -> 14 | C15: Pack Cuidado Facial Avene Sérum Vitamina Cg 30ML + Protector Solar Fluido Mineral SPF 50+ 40ML | D15: =LEN(C15) -> 94 | E15: 389.5 | F15: Antiedad, Antimanchas, Facial | G15: Antiedad | H15: =VLOOKUP(G15,Hoja1!B:C,2,0) -> #N/A | J15: 1. Para el Sérum Vitamina Cg: Limpia y seca tu rostro. Usa la pipeta para aplicar unas gotas en rostro, cuello y escote, masajeando hasta absorber. Usa mañana y noche antes de la crema hidratante. 2. Para el Protector Solar Fluido Mineral: Antes de la exposición al sol, agita el envase y aplica generosamente en el rostro de manera uniforme. | K15: Piel sensible | L15: Vitamina Cg (1.8%): Potente antioxidante que ilumina y protege la piel, Niacinamida (3%): Mejora la barrera cutánea y reduce manchas, Bakuchiol (1.5%): Alternativa natural al retinol que corrige arrugas sin irritar, Complejo Mineral (Óxido de Zinc): Protección solar física de amplio espectro para pieles sensibles. | M15: ¡Transforma y protege tu piel con este pack esencial de Avene! Este combo incluye el Sérum Vitamina Cg de 30ML, un corrector e iluminador que combate manchas, arrugas y flacidez con una fórmula rica en antioxidantes como Vitamina Cg, Niacinamida y Bakuchiol, ofreciendo un 94% de ingredientes naturales para una piel más suave y radiante en 15 días. Junto a él, el Protector Solar Fluido Mineral SPF 50+ de 40ML, con filtros 100% minerales, textura ligera y acabado mate, ofrece protección de amplio espectro UVB-UVA muy resistente al agua, ideal para pieles sensibles e intolerantes. ¡La dupla perfecta para un cuidado facial completo, eficaz y respetuoso! | N15: Avene | O15: 0.25 | P15: Unisex | Q15: Vitamina Cg Serum + Solar Fluido Mineral | R15: 1 frasco de Avene Vitamina Cg Serum 30ML, 1 frasco de Avene Solar Fluido Mineral SPF 50+ 40 ML Sin Color. | S15: Pack de Sérum y Protector Solar Facial | T15: 70 mL | U15: Sin Color | V15: 8 | W15: 18 | X15: 5 | Y15: avene, serum vitamina c, protector solar mineral, antiedad, antimanchas, piel sensible, spf 50+, fluido, antioxidante | Z15: 70 | AA15: Sérum corrector e iluminador, Protector solar de amplio espectro, Fórmula con 94% ingredientes naturales, Filtros 100% minerales, Textura ligera y de rápida absorción, Resistente al agua, Acabado mate, Sin perfume, Para piel sensible | AB15: pack avene, serum vitamina c avene, protector solar mineral avene, cuidado facial, antiedad, antimanchas, spf 50, fluido solar, piel sensible, sérum iluminador | AC15: Transparente | AD15: 0.2 | AE15: Pack Avene: Sérum Vitamina Cg + Protector Solar Mineral SPF50+ | AF15: Sérum: Agua termal de Avene, Vitamina Cg (Ascorbil Glucósido), Niacinamida, Bakuchiol, y otros ingredientes naturales. Protector Solar: Agua termal de Avene, Óxido de Zinc (filtro mineral), emolientes y agentes texturizantes para una aplicación fluida y acabado mate. | AG15: Pierre Fabre | AH15: Pack Avene con Sérum Vitamina Cg para corregir arrugas y manchas, y Protector Solar Mineral SPF50+ para piel sensible. Combate el envejecimiento y protege diariamente. ¡Resultados visibles en 15 días! | AI15: null | AJ15: Kit de Cuidado de la Piel | AK15: MPE123356 | AL15: TRATAMIENTOS Y DERMOCOSMETICA > DERMOCOSMETICA | AM15: R300806000000 | AN15: Cuidado de la piel|hidratación de la piel | AO15: 2257
A16: 094-001-003 | C16: Pack Dúo Martiderm Eye Correct - Tratamiento Día y Noche para Contorno de Ojos | D16: =LEN(C16) -> 78 | E16: 222.52 | F16: Antiojeras, Antiedad, Facial | G16: Antiojeras | H16: =VLOOKUP(G16,Hoja1!B:C,2,0) -> #N/A | I16: Facial | J16: 1. Aplicar suavemente una pequeña cantidad de producto sobre el contorno del ojo. 2. Realizar un suave masaje, desde el extremo exterior hasta el lagrimal. 3. Para el tratamiento de día (Eye Correct Day), masajear hasta obtener un color uniforme. 4. Para el tratamiento de noche (Eye Correct Night), masajear hasta su total absorción. | K16: Todo tipo de piel | L16: Hemomelan KX Complex (reduce y disimula ojeras), Tetrapeptide (acción antiedad), EGCG (descongestionante y antioxidante), Vitamina E (protectora y calmante), Biosabolol (calmante y antiinflamatorio) | M16: ¡Descubre la mirada luminosa y descansada que siempre has querido! Presentamos el Pack Doble de Martiderm Eye Correct, un tratamiento revolucionario de día y noche específicamente formulado para el contorno de ojos. Este pack incluye dos unidades completas, cada una con su fórmula dual: Eye Correct Day, una emulsión hidratante ligera con color que unifica el tono e ilumina la mirada, y Eye Correct Night, un gel-crema hidratante que trabaja mientras descansas para una mirada más fresca al despertar. Su avanzada tecnología con Hemomelan KX Complex y péptidos actúa reduciendo visiblemente bolsas y ojeras, ofreciendo un efecto descongestionante inmediato con sensación de frescor. Fabricado con ingredientes de alta eficacia como EGCG y Biosabolol, es ideal para un cuidado diario profesional en casa. ¡Consigue un contorno de ojos rejuvenecido y dile adiós a los signos de fatiga con este tratamiento completo! | N16: Martiderm | O16: 0.25 | P16: Unisex | Q16: Eye Correct | R16: 2 unidades del tratamiento Martiderm Eye Correct. Cada unidad contiene 2 productos: 1 emulsión Eye Correct Day y 1 gel-crema Eye Correct Night. | S16: Tratamiento para contorno de ojos | T16: 2 pzas | V16: 4 | W16: 12 | X16: 4 | Y16: contorno de ojos, antiojeras, anti bolsas, día y noche, tratamiento facial, piel sensible, iluminador, descongestionante | AA16: Fórmula Day & Night, Reduce bolsas y ojeras, Efecto iluminador inmediato, Textura ligera no grasa, Descongestionante y calmante, Para todo tipo de piel | AB16: martiderm eye correct, contorno de ojos, crema para ojeras, tratamiento antiojeras, reducir bolsas ojos, cuidado ojos día y noche, cosmética facial, piel sensible | AD16: 0.1 | AE16: Pack Martiderm Eye Correct - Tratamiento Día/Noche Contorno Ojos | AF16: Emulsión y gel-crema formulados con una combinación de activos como el Hemomelan KX Complex para corregir la coloración, péptidos antiedad, antioxidantes como el EGCG del té verde, Vitamina E protectora y Biosabolol calmante. Diseñados para hidratar, iluminar y tratar los signos de fatiga en la zona del contorno ocular. | AH16: Pack con 2 unidades de Martiderm Eye Correct. Tratamiento día y noche que reduce bolsas y ojeras, ilumina y descongestiona el contorno de ojos. Fórmula con péptidos y antioxidantes para todo tipo de piel. ¡Mirada fresca y descansada! | AJ16: Cuidado Facial | AK16: MPE392452 | AL16: TRATAMIENTOS Y DERMOCOSMETICA > DERMOCOSMETICA | AM16: R300806000000 | AN16: Cosméticos|ojos | AO16: 2945 | AP16: Este pack contiene 2 unidades del tratamiento Martiderm Eye Correct, cada una incluye una fórmula de día y otra de noche para el contorno de ojos.
A17: 109-001-002 | B17: =VLOOKUP(A17,Hoja1!B:C,2,0) -> 15 | C17: Pack Dúo Sesderma Hidraderm Hyal Crema Facial con Ácido Hialurónico Liposomado | D17: =LEN(C17) -> 78 | E17: 209 | F17: Hidratante, Antiedad, Facial | G17: Hidratante | H17: =VLOOKUP(G17,Hoja1!B:C,2,0) -> #N/A | J17: 1. Aplica la crema sobre el rostro, cuello y escote limpios y secos. 2. Realiza un suave masaje con las yemas de los dedos hasta su completa absorción. 3. Utiliza la cantidad equivalente a presionar la bomba dosificador 3 veces para una cobertura uniforme. 4. Puedes aplicarla tanto por la mañana como por la noche. | K17: Piel Normal a Seca | L17: Ácido Hialurónico de alto peso molecular (hidrata y forma una película protectora en la superficie), Ácido Hialurónico de bajo peso molecular liposomado (penetra en capas más profundas para hidratación interna), Ácido Hialurónico de muy bajo peso molecular liposomado (actúa en las capas más profundas de la piel para una hidratación intensa) | M17: ¡Consigue una piel hidratada, rejuvenecida y protegida con este pack doble de lujo! El Pack Doble Sesderma Hidraderm Hyal Crema Facial es tu solución definitiva para la hidratación profunda y el tratamiento anti-edad. Esta crema facial de alta eficacia está formulada con una tecnología avanzada de Ácido Hialurónico en tres pesos moleculares diferentes (alto, bajo y muy bajo), este último encapsulado en liposomas para una penetración óptima. Su innovadora fórmula permite hidratar la piel a múltiples niveles: desde la superficie, creando un efecto filmógeno protector, hasta las capas más profundas de la dermis. Ideal para pieles secas, deshidratadas e incluso sensibles, ayuda a combatir los signos del envejecimiento causados por factores externos como el clima o internos como la edad. También es perfecta para recuperar la piel después de tratamientos estéticos agresivos como peelings o láser. ¡Invierte en la salud de tu piel y disfruta de un rostro suave, elástico y luminoso con este tratamiento profesional en la comodidad de tu hogar! | N17: Sesderma | O17: 0.3 | P17: Unisex | Q17: Hidraderm Hyal | R17: 2 unidades de Crema Facial Sesderma Hidraderm Hyal | S17: Crema Facial Hidratante con Ácido Hialurónico | T17: 2 pzas | U17: Blanco | V17: 6 | W17: 15 | X17: 6 | Y17: ácido hialurónico, crema facial, hidratante, antiarrugas, sesderma, piel seca, liposomado, antiedad, cuidado facial, tratamiento | AA17: Hidratación multinivel, Tecnología liposomada, Para pieles sensibles, Anti-envejecimiento, Recuperación post-tratamiento, Aplicación día y noche | AB17: pack sesderma hidraderm, crema acido hialuronico, hidratante facial, tratamiento antiedad, crema para piel seca, sesderma pack doble, crema facial hidratante, antiarrugas, piel deshidratada, cuidado de la piel | AC17: Blanco | AD17: 0.12 | AE17: Pack Doble Crema Facial Sesderma Hidraderm Hyal - Ácido Hialurónico | AF17: Formulada con una combinación de tres tipos de Ácido Hialurónico: de alto peso molecular libre para hidratación superficial y efecto filmógeno; y de bajo y muy bajo peso molecular, encapsulados en liposomas para garantizar su liberación controlada y penetración profunda en la piel, proporcionando hidratación intensa y duradera. | AG17: Sesderma | AH17: Pack de 2 cremas faciales Sesderma con Ácido Hialurónico liposomado. Hidratación profunda multinivel, trata piel seca/deshidratada y signos de envejecimiento. Ideal para uso diario y post-tratamientos estéticos. | AJ17: Cuidado Facial | AK17: MPE392452 | AL17: TRATAMIENTOS Y DERMOCOSMETICA > DERMOCOSMETICA | AM17: R300806000000 | AN17: Cuidado de la piel|hidratación de la piel | AO17: 2257 | AP17: Este pack contiene 2 unidades de Sesderma Hidraderm Hyal Crema Facial.
A18: 136-001-012 | B18: =VLOOKUP(A18,Hoja1!B:C,2,0) -> 16 | C18: Pack Dúo Bioderma Atoderm Huile De Douche FP1L (x2) - Aceite de Ducha para Piel Muy Seca y Atópica | D18: =LEN(C18) -> 98 | E18: 179.9 | F18: Piel seca, Piel Atópica, Calmante | G18: Piel seca | H18: =VLOOKUP(G18,Hoja1!B:C,2,0) -> #N/A | J18: 1. Aplicar sobre la piel húmeda durante la ducha o el baño. 2. Masajear suavemente para crear una espuma ultraligera. 3. Aclarar completamente con agua. 4. Para mejores resultados, seguir con un tratamiento de la gama Atoderm. Se recomienda usar una o dos veces al día. | K18: Piel sensible muy seca, irritada, atópica | L18: Biolípidos vegetales: reconstruyen la película protectora y alivian la tirantez, Vitamina B3 (Niacinamida): estimula la síntesis de lípidos para reconstruir la barrera cutánea, Patente Skin Barrier Therapy™: previene la adhesión de bacterias que empeoran la irritación, Complejo DAF: aumenta la tolerancia de la piel. | M18: ¡Transforma tu rutina de baño en un ritual de cuidado intensivo! Este pack incluye dos botellas de 1 litro del Aceite de Ducha Bioderma Atoderm, un limpiador diseñado específicamente para pieles muy secas, irritadas y atópicas. Su fórmula exclusiva, enriquecida con biolípidos vegetales, vitamina B3 (Niacinamida) y la patente Skin Barrier Therapy™, no solo limpia con suavidad sino que calma, protege y refuerza la barrera cutánea contra agresiones externas. Ofrece 24 horas de hidratación, es muy nutritivo y protector, con una espuma ultraligera y una textura aceitosa cremosa que no reseca. Su excelente tolerancia cutánea y ocular, junto con un perfume suave, lo hacen ideal para toda la familia. ¡Consigue una piel calmada, hidratada y protegida con cada ducha! | N18: Bioderma | O18: 2.2 | P18: Unisex | Q18: Huile De Douche FP1L | R18: 2 botellas de Bioderma Atoderm Huile De Douche de 1000 mL (1L) cada una. | S18: Aceite de ducha o gel de baño | T18: 2 x 1000 mL | U18: null | V18: 10 | W18: 20 | X18: 10 | Y18: bioderma, atoderm, aceite de ducha, piel atópica, piel seca, hidratante, calmante, gel de baño, limpieza suave, dermatológico | Z18: 2000 | AA18: Hidratación 24H, Limpieza suave, Textura aceite cremoso, Sin jabón, No comedogénico, Perfume suave, No pica en los ojos, Para piel sensible | AB18: bioderma atoderm, aceite de ducha bioderma, gel baño piel seca, producto piel atópica, limpiador corporal, hidratante ducha, pack bioderma, oferta bioderma | AC18: null | AD18: 2 | AE18: Pack Bioderma Atoderm Aceite Ducha Piel Atópica 2x1L | AF18: Agua, Glicerina (humectante), tensioactivos suaves derivados del coco (PEG-7 Glyceryl Cocoate, Sodium Cocoamphoacetate) para limpiar sin agredir, Biolípidos vegetales para reconstruir la barrera lipídica, Niacinamida (Vitamina B3) para reparar la piel, y fragancia suave. | AG18: Bioderma | AH18: Pack con 2 aceites de ducha Bioderma Atoderm de 1L. Calma y protege pieles muy secas y atópicas con biolípidos y vitamina B3. Hidratación 24H y limpieza suave. ¡Compra ahora! | AI18: Perfume suave | AJ18: Cuidado Corporal | AK18: MPE392701 | AL18: BAÑO Y SPA > GEL DE DUCHA | AM18: R300202000000 | AN18: Cabello|champús | AO18: 3190 | AP18: Este pack contiene 2 unidades de Bioderma Atoderm Huile De Douche FP1L, aceite de ducha de 1 litro cada una.
